Workbook

Sheet Ligand cost
I1: ChemScene | J1: $1850/kg ddFc
A3: 1. Synthesis of ddFc
A13: Chemicals | B13: Formula | C13: MW | D13: eq | E13: mol | F13: g | G13: Yield(%) | H13: Price ($) | I13: Unit Price | J13: Unit | K13: vol (ml) | L13: d (g/ml) | M13: Source
A14: Ferrocene | B14: C10H10Fe | C14: 186.03 | D14: 1 | E14: =F14/C14 -> 0.096758587 | F14: 18 | H14: =I14*F14/1000 -> 0.504 | I14: 28 | J14: $/kg | M14: https://www.chemicalbook.com/ProductDetail_EN_ferrocene_2034577.htm
A15: Dodecanoyl chloride | B15: C12H23ClO | C15: 218.76 | D15: 2 | E15: =F15/C15 -> 0.19349973 | F15: 42.33 | H15: =I15*F15/1000 -> 0.160854 | I15: 3.8 | J15: $/kg | K15: 45.9 | L15: 0.922 | M15: https://www.chemicalbook.com/ProductDetail_EN_991682.htm
A16: NaBH4 | B16: BH4Na | C16: 37.83 | D16: 2 | E16: =F16/C16 -> 0.19352366 | F16: 7.321 | H16: =I16*F16/1000 -> 0.102494 | I16: 14 | J16: $/kg | M16: https://www.alibaba.com/product-detail/Free-Sample-Sodium-Borocyanohydride-CAS-25895_10000026309495.html?spm=a2700.galleryofferlist.normal_offer.d_title.462413a0yX9EqR&priceId=0638c4062c394ca3b92a5c9dc07a2423 Organic Intermediate Sodium Cyanoborohydride Product on Alibaba.com
A17: Triethylene glycol dimethyl ether | B17: C8H18O4 | C17: 178.23 | D17: =E17/E14 -> 5.5322583 | E17: =F17/C17 -> 0.5352935 | F17: =K17*L17 -> 95.40536 | H17: =I17*F17/1000 -> 1.0112968 | I17: 10.6 | J17: $/kg | K17: 96.76 | L17: 0.986 | M17: https://www.chemicalbook.com/ProductDetail_EN_1414752.htm
A18: Aluminum trichloride | B18: AlCl3 | C18: 133.33 | D18: 2.2 | E18: =F18/C18 -> 0.21285532 | F18: 28.38 | H18: =I18*F18/1000 -> 0.05676 | I18: 2 | J18: $/kg | M18: https://www.chemicalbook.com/ProductDetail_EN_aluminum-chloride_2179085.htm
A19: Dichloromethane | B19: CH2Cl2 | C19: 84.93 | D19: =E19/E14 -> 80.922819 | E19: =F19/C19 -> 7.8299776 | F19: 665 | H19: =I19*F19/1000 -> 6.65 | I19: 10 | J19: $/kg | K19: 500 | L19: 1.33 | M19: https://www.chemicalbook.com/ProductDetail_EN_1480688.htm
A20: Bis(lauryl)ferrocene (ddFc) | B20: C34H58Fe | C20: 522.68 | F20: 27.81 | G20: 54.99 | H20: =SUM(H14:H19) -> 8.4854048 | J20: =H20/F20 -> 0.30512063
J21: $/g
A22: 2. Synthesis of deFc
J23: =J20*1000 -> 305.12063
A33: Chemicals | B33: Formula | C33: MW | D33: eq | E33: mol | F33: g | G33: Yield(%) | H33: Price ($) | I33: Unit Price | J33: Unit | K33: vol (ml) | L33: d (g/ml) | M33: Source
A34: Carbomethoxyferrocene | B34: C12H12FeO2 | C34: 244.07 | D34: 1 | E34: =F34/C34 -> 0.069652149 | F34: 17 | H34: =I34*F34/1000 -> 63.24 | I34: 3720 | J34: $/kg | M34: https://scifinder-n.cas.org/searchDetail/catalogItem/6972747ff639fa3449303d77/catalogItemDetails
A35: Dodecanoyl chloride | B35: C12H23ClO | C35: 218.76 | D35: 2 | E35: =F35/C35 -> 0.13933077 | F35: 30.48 | H35: =I35*F35/1000 -> 0.115824 | I35: 3.8 | J35: $/kg | K35: 33.1 | L35: 0.922 | M35: https://www.chemicalbook.com/ProductDetail_EN_991682.htm
A36: NaBH4 | B36: BH4Na | C36: 37.83 | D36: 2 | E36: =F36/C36 -> 0.13930743 | F36: 5.27 | H36: =I36*F36/1000 -> 0.07378 | I36: 14 | J36: $/kg | M36: https://www.alibaba.com/product-detail/Free-Sample-Sodium-Borocyanohydride-CAS-25895_10000026309495.html?spm=a2700.galleryofferlist.normal_offer.d_title.462413a0yX9EqR&priceId=0638c4062c394ca3b92a5c9dc07a2423 Organic Intermediate Sodium Cyanoborohydride Product on Alibaba.com
A37: Triethylene glycol dimethyl ether | B37: C8H18O4 | C37: 178.23 | D37: =E37/E34 -> 5.5320068 | E37: =F37/C37 -> 0.38531616 | F37: =K37*L37 -> 68.6749 | H37: =I37*F37/1000 -> 0.72795394 | I37: 10.6 | J37: $/kg | K37: 69.65 | L37: 0.986 | M37: https://www.chemicalbook.com/ProductDetail_EN_1414752.htm
A38: Aluminum trichloride | B38: AlCl3 | C38: 133.33 | D38: 2.2 | E38: =F38/C38 -> 0.15322883 | F38: 20.43 | H38: =I38*F38/1000 -> 0.04086 | I38: 2 | J38: $/kg | M38: https://www.chemicalbook.com/ProductDetail_EN_aluminum-chloride_2179085.htm
A39: Dichloromethane | B39: CH2Cl2 | C39: 84.93 | D39: =E39/E34 -> 89.93236 | E39: =F39/C39 -> 6.2639821 | F39: 532 | H39: =I39*F39/1000 -> 5.32 | I39: 10 | J39: $/kg | K39: 400 | L39: 1.33 | M39: https://www.chemicalbook.com/ProductDetail_EN_1480688.htm
A40: 1-lauryl-1'-carbomethoxy ferrocene | B40: 412.4 | F40: 19.77 | G40: 68.83 | H40: =SUM(H34:H39) -> 69.518418 | J40: =H40/F40 -> 3.516359
J41: $/g
A45: 3. Synthesis of coeFc
A47: Chemicals | B47: Formula | C47: MW | D47: eq | E47: mol | F47: g | G47: Yield(%) | H47: Price ($) | I47: Unit Price | J47: Unit | K47: vol (ml) | L47: d (g/ml) | M47: Source
A48: Ferrocene carboxaldehyde | B48: C11H10FeO | C48: 214.04 | D48: 1 | E48: 0.018688096 | F48: 4 | H48: =I48*F48/1000 -> 8.1888 | I48: 2047.2 | J48: $/kg | M48: https://store.apolloscientific.co.uk/product/ferrocenecarboxaldehyde
A49: Octyl cyanoacetate | B49: NCCH2CO2(CH2)7CH3 | C49: 197.27 | D49: 1.4 | E49: 0.026157044 | F49: 5.16 | H49: =I49*F49/1000 -> 0.0516 | I49: 10 | J49: $/kg | M49: https://www.chemicalbook.com/ProductList_En.aspx?kwd=15666-97-4
A50: Piperidine | B50: C5H11N | C50: 85.15 | D50: 0.1 | E50: 0.001867293 | F50: 0.159 | H50: =I50*F50/1000 -> 0.07155636 | I50: 450.04 | J50: $/kg | M50: https://scifinder-n.cas.org/searchDetail/catalogItem/69baf576d2558453e28ba6ad/catalogItemDetails
A51: Ethyl alcohol | B51: CH3CH2OH | C51: 46.07 | D51: 5.4706338 | E51: 0.10223573 | F51: 4.71 | H51: =I51*F51/1000 -> 0.0002355 | I51: 0.05 | J51: $/kg | K51: 6 | L51: 0.785 | M51: https://www.chemicalbook.com/ProductList_En.aspx?kwd=ethanol
A52: Dichloromethane | B52: CH2Cl2 | C52: 84.93 | D52: 83.796421 | E52: 1.5659955 | F52: 133 | H52: =I52*F52/1000 -> 1.33 | I52: 10 | J52: $/kg | K52: 100 | L52: 1.33 | M52: https://www.chemicalbook.com/ProductDetail_EN_1480688.htm
A53: Hydrochloric acid | B53: HCl | C53: 36.46 | D53: 14.46267 | E53: 0.27027976 | F53: 9.8544 | H53: =I53*F53/1000 -> 0.12367272 | I53: 12.55 | J53: $/kg | K53: 8.212 | L53: 1.2 | M53: https://scifinder-n.cas.org/searchDetail/catalogItem/69baf9c8d2558453e28bd0fe/catalogItemDetails
A54: n-hexane | B54: CH3(CH2)4CH3 | C54: 86.18 | D54: 294.16219 | E54: 5.4973312 | F54: 473.76 | H54: =I54*F54/1000 -> 4.7376 | I54: 10 | J54: $/kg | K54: 720 | L54: 0.658 | M54: https://www.chemicalbook.com/ProductList_En.aspx?kwd=%20110-54-3
A55: Ethyl acetate | B55: CH3COOC2H5 | C55: 88.11 | D55: 98.602697 | E55: 1.8426966 | F55: 162.36 | H55: =I55*F55/1000 -> 1.6236 | I55: 10 | J55: $/kg | K55: 180 | L55: 0.902 | M55: https://www.chemicalbook.com/ProductList_En.aspx?kwd=141-78-6
A56: coeFc | B56: 393.31 | F56: 6.23 | G56: 84.6 | H56: =SUM(H48:H55) -> 16.127065 | J56: =H56/F56 -> 2.5886139
J57: $/g
J59: =J56*1000 -> 2588.6139

Sheet Reagent cost
C1: Vol of solution | D1: 100 | E1: L | I1: 100
C3: %excess | D3: 1.2 | E3: 2.25 | M3: conc. | O3: volume
B4: 1 | D4: 8 | F4: 6 | H4: 3 | J4: 3 | L4: feed | O4: 100 | P4: L/min | S4: =_xlfn.T.INV(1-0.05/2,14) -> 2.1447867
B5: KIO3 | C5: + | D5: NaI | E5: + | F5: HClO4 | G5: = | H5: I3- | J5: H2O | L5: oxidant | M5: 100 | N5: mM | O5: 100 | P5: L
A6: Conc (mM): | B6: =(H6/3)*D3 -> 40 | D6: =(8*H6/3)*E3 -> 600 | F6: =H6*2 -> 200 | H6: 100 | I6: 10 | L6: reductant | M6: 100 | N6: mM | O6: 100 | P6: L | S6: =1822.191-2.145*300.199 -> 1178.2641
F7: Limiting Rctnt | L7: ligand | M7: 100 | N7: mM | O7: 300 | P7: L
L8: change salt to be included in PGM feed Salt of conc 0.1 M
S9: =0.2832+2.145*0.0106 -> 0.305937
A10: Chemicals | B10: Formula | C10: MW | D10: mol (M) | E10: kg | F10: vol (L) | G10: d (g/ml) | H10: Unit Price | I10: Unit | J10: Price | K10: Source
A11: Dichloromethane | B11: CH2Cl2 | C11: 84.93 | E11: =F11*G11 -> 132 | F11: 100 | G11: 1.32 | H11: 10 | I11: $/kg | J11: =E11*H11 -> 1320 | K11: https://www.chemicalbook.com/ProductList_En.aspx?kwd=dichloromethane
A12: ox | B12: KIO3 | C12: 214.001 | D12: 0.04 | E12: =D12*$D$1*C12/1000 -> 0.856004 | F12: 100 | H12: 10 | I12: $/kg | J12: =E12*H12 -> 8.56004 | K12: https://www.chemicalbook.com/ProductList_En.aspx?cbn=CB5854303
A13: ox | B13: NaI | C13: 149.8942 | D13: 0.6 | E13: =D13*$D$1*C13/1000 -> 8.993652 | F13: 100 | H13: 4 | I13: $/kg | J13: =E13*H13 -> 35.974608 | K13: https://www.chemicalbook.com/ProductList_En.aspx?cbn=CB6170714
A14: ox | B14: HClO4 | C14: 100.46 | D14: 0.2 | E14: =D14*$D$1*C14/1000 -> 2.0092 | F14: 100 | H14: 63.5 | I14: $/L | J14: =E14*H14 -> 127.5842 | K14: https://scifinder-n.cas.org/searchDetail/catalogItem/698a4af308f8b56fea0b2a9f/catalogItemDetails
K15: Perchloric acid, 0.1N in Acetic Acid Standardized Solution
A16: red | B16: K4Fe(CN)6∙3H2O | C16: 422.39 | D16: 0.1 | E16: =D16*$D$1*C16/1000 -> 4.2239 | F16: 100 | H16: 10 | I16: $/kg | J16: =E16*H16 -> 42.239 | K16: https://scifinder-n.cas.org/searchDetail/catalogItem/698a50ae08f8b56fea0b847a/catalogItemDetails
A17: salt | B17: NaCl | C17: 58.44 | D17: 0.1 | E17: =D17*$D$1*C17/1000 -> 0.5844 | F17: 100 | H17: 2 | I17: $/kg | J17: =E17*H17 -> 1.1688 | K17: https://www.chemicalbook.com/ProductList_En.aspx?cbn=CB4104636
A18: ddFc | B18: C34H58Fe | C18: 522.68 | D18: 0.1 | E18: =D18*F18*C18/1000 -> 15.6804 | F18: 300 | H18: ='Ligand cost'!J20*1000 -> 305.12063 | I18: $/kg | J18: =E18*H18 -> 4784.4136
A19: FeCl2 | C19: 126.75 | H19: 1 | I19: $/kg | K19: https://www.chemicalbook.com/ChemicalProductProperty_EN_CB5411955.htm
I20: sum | J20: =SUM(J11:J18) -> 6319.9402
A23: deFc | C23: 412.21 | D23: 0.1 | H23: 3267.1774 | I23: $/kg
I26: DCM 1% makeup, ligand 2% makeup
H27: reagent opex | J27: =(J11*0.01+J18*0.02)*300 -> 32666.481 | K27: $/year
B28: 50% wt perchloric acid
A29: 35.31 | B29: https://www.alibaba.com/product-detail/inorganic-acid-perchloric-acid-50-Purity_1601345200625.html?spm=a2700.7724857.0.0.798331f2XzNuo4
A32: Chemicals | B32: Formula | C32: Unit Price | D32: units
A33: Dichloromethane | B33: CH2Cl2 | D33: $/L
A34: ox | B34: KIO3 | C34: =H12/1000*C12 -> 2.14001 | D34: $/mol
A35: ox | B35: NaI | C35: =H13/1000*C13 -> 0.5995768 | D35: $/mol
A36: ox | B36: HClO4 | C36: =A29*2 -> 70.62 | D36: $/kg pure
A38: red | B38: K4Fe(CN)6∙3H2O | C38: =H16/1000*C16 -> 4.2239 | D38: $/mol
A39: salt | B39: NaCl | C39: =H17/1000*C17 -> 0.11688 | D39: $/mol
A40: ddFc | B40: C34H58Fe | C40: =H18/1000*C18 -> 159.48045 | D40: $/mol
A41: FeCl2 | D41: $/mol

Sheet Oxidant Feed Composition
A1: Chemical
D3: Vol of solution | E3: 100 | F3: L | G3: Mols Water Init --> | H3: 5550.84
D5: Water generated is negligible relative to vol--> can assume constant volume
A7: x excess: | B7: 1.2 | D7: 2.25
A8: Stoich: | B8: 1 | D8: 8 | F8: 6 | H8: 3 | J8: 3 | L8: 6 | N8: Assume K is analogous with Na for Atom balance check purposes
B9: NaIO3 | C9: + | D9: NaI | E9: + | F9: HClO4 | G9: = | H9: NaI3 | I9: + | J9: H2O | K9: + | L9: NaClO4 | N9: NaIO3 should really be KIO3, but we will use Na as a placeholder for all cations, so K4[Fe(CN)_6] will be assumed to be Na4[Fe(CN)_6]
A10: Conc (mM): | B10: =(H10/3)*B7 -> 40 | D10: =(8*H10/3)*D7 -> 600 | F10: =H10*2 -> 200 | H10: 100 | J10: 100 | L10: 200
A11: conc (M): | B11: =B10/1000 -> 0.04 | D11: =D10/1000 -> 0.6 | F11: =F10/1000 -> 0.2 | H11: =H10/1000 -> 0.1 | J11: =J10/1000 -> 0.1 | L11: =L10/1000 -> 0.2
A12: I (mol): | B12: =$E$3*B11 -> 4 | D12: =$E$3*D11 -> 60 | F12: =$E$3*F11 -> 20 | H12: 0 | J12: 0 | L12: 0
A13: delta (mol): | B13: =1/6*F13 -> -3.3333333 | D13: =4/3*F13 -> -26.666667 | F13: =-F12 -> -20 | H13: =-1/2*F13 -> 10 | J13: =-1/2*F13 -> 10 | L13: =-1*F13 -> 20
A14: F (mol): | B14: =B12+B13 -> 0.66666667 | D14: =D12+D13 -> 33.333333 | F14: =F12+F13 -> 0 | H14: =H12+H13 -> 10 | J14: =J12+J13 -> 10 | L14: =L12+L13 -> 20
A15: F Conc (M) | B15: =B14/$E$3 -> 0.0066666667 | D15: =D14/$E$3 -> 0.33333333 | F15: =F14/$E$3 -> 0 | H15: =H14/$E$3 -> 0.1 | J15: =J14/$E$3 -> 0.1 | L15: =L14/$E$3 -> 0.2
A18: Chemicals In Process | B18: Description | M18: Oxidant Feed Tank Composition
A19: H2[PtCl_6] | B19: Chloroplatinic Acid in OG Leachate Feed | M19: Chemical | N19: Conc [M] | O19: MW [g/mol]
A20: Na2[PdCl_4] | B20: Chloropalladic Acid in OG Leachate Feed | L20: really K | M20: NaIO3 | N20: =B15 -> 0.0066666667 | O20: 214.001 | P20: Kio3 MW
A21: Na3[RhCl_6] | B21: Chlororhodic Acid in OG Leachate Feed | M21: NaI | N21: =D15 -> 0.33333333 | O21: 149.89
A22: HCl | B22: Will Likely Be in Feed Leachate. Inert in eLLE | M22: NaI3 | N22: =H15 -> 0.1
A23: NaCl | B23: Will Likely Be in Feed Leachate. Also in aqueous reduction loop. Inert in eLLE | M23: NaClO4 | N23: =L15 -> 0.2
A24: KIO3 | B24: Enters in Aqueous Oxidant Loop | M24: Cost For 100 L of Feed Solution [$] | N24: =B12*'Reagent cost'!C34+D12*'Reagent cost'!C35+F12*'Reagent cost'!C36*'Reagent cost'!C14/1000 -> 186.42435
A25: NaI | B25: Enters in Aqueous Oxidant Loop | M25: Cost Ox Fresh Feed [$/L] | N25: =N24/100 -> 1.8642435
A26: NaI3 | B26: Enters in Aqueous Oxidant Loop | M26: Cost per mol NaI3- [$/mol] | N26: =N24/(100*N22) -> 18.642435
A27: NaClO4 | B27: Enters in Aqueous Oxidant Loop | M27: HClO4 | O27: 100.46
M28: Cost Ox Fresh Feed +50% ClO4 Price [$/L] | N28: =(B12*'Reagent cost'!C34+D12*'Reagent cost'!C35+F12*'Reagent cost'!C36*'Reagent cost'!C14/1000*1.5)/100 -> 2.573692
M29: Cost Ox Fresh Feed -50% ClO4 Price [$/L] | N29: =(B12*'Reagent cost'!C34+D12*'Reagent cost'!C35+F12*'Reagent cost'!C36*'Reagent cost'!C14/1000*0.5)/100 -> 1.154795
E39: assume ddFc of 1.89 mol/min (3 stages S1)
E40: =1.89/0.2 -> 9.45 | F40: =E40*0.006666666666 -> 0.063
B44: NaClO4 | C44: + | D44: NaI3 | E44: + | F44: ddFc | G44: = | H44: ddFcClO4 | I44: + | J44: NaI
B45: 1 | D45: 0.5 | F45: 1 | H45: 1 | J45: 1.5
A46: I (mol/min) | B46: 1.89 | D46: =F46*D45*1.2 -> 1.134 | F46: 1.89 | H46: 0 | J46: 3.78
A47: delta (mol/min) | B47: =$F$47*B45 -> -1.89 | D47: =$F$47*D45 -> -0.945 | F47: =-F46 -> -1.89 | H47: =-$F$47*H45 -> 1.89 | I47: =-$F$47*I45 -> 0 | J47: =-$F$47*J45 -> 2.835
A48: F (mol/min) | B48: =B46+B47 -> 0 | C48: =C46+C47 -> 0 | D48: =D46+D47 -> 0.189 | E48: =E46+E47 -> 0 | F48: =F46+F47 -> 0 | G48: =G46+G47 -> 0 | H48: =H46+H47 -> 1.89 | I48: =I46+I47 -> 0 | J48: =J46+J47 -> 6.615

Sheet PGM market prices
B1: Name | C1: price/kg (USD/kg) | D1: $/troy oz | F1: Source
B2: Pt | C2: =D2/0.031 -> 33730.323 | D2: 1045.64 | F2: PGM prices and trading | Johnson Matthey
B3: Pd | C3: =D3/0.031 -> 32929.677 | D3: 1020.82 | F3: assessed on August 11th 2025 last 12 months average price
B4: Rh | C4: =D4/0.031 -> 164946.13 | D4: 5113.33
B5: Ru | C5: =D5/0.031 -> 17831.613 | D5: 552.78
B6: Ir | C6: =D6/0.031 -> 142484.52 | D6: 4417.02
E9: 43200000
B10: 100 L/min feed 1000 ppm of PGM each | F10: =E9/2 -> 21600000 | G10: kg/year
D11: Pt | F11: =C2*$F$10 -> 7.2857497e+11 | G11: $
B12: 50% recovery assumed | D12: Pd | F12: =C3*$F$10 -> 7.1128103e+11 | G12: $
D13: Rh | F13: =C4*$F$10 -> 3.5628364e+12 | G13: $
D14: Ru | F14: =C5*$F$10 -> 3.8516284e+11 | G14: $
D15: Ir | F15: =C6*$F$10 -> 3.0776655e+12 | G15: $ | J15: Platinum PRICE Today | Platinum Spot Price Chart | Live Price of Platinum per Ounce | Markets Insider
J16: PGM prices and trading | Johnson Matthey
J17: USGS

Sheet CAPEX+OPEX
A1: Electrolyzer unit | D1: 00 21-0083-SI.fm | M1: Executive summary – Global Hydrogen Review 2025 – Analysis - IEA
A2: CAPEX | M2: The cost of making and installing an electrolyser outside of China in 2024 was USD 2 000 to USD 2 600 per kilowatt (kW)
A3: oxidant/reductant conc | C3: 0.1 | D3: mol/L
A4: volume | C4: 100 | D4: L | M4: Economics of converting renewable power to hydrogen | Nature Energy
A5: Q | C5: =C3*C4*96485 -> 964850 | D5: C | M5: Electrolyzer capital cost $550/kW-2640/kW
A6: current density | C6: 4 | D6: A/m2 | E6: 0.4 | F6: mA/cm2
A7: cell voltage | C7: 0.5 | D7: V | M7: Electrolyzer energy dominates separation costs in state-of-the-art CO2 electrolyzers: Implications for single-pass CO2 utilization: Joule
A8: area | C8: 0.0005 | D8: m2
A10: electrolyzer cost per area | C10: 31871 | D10: $/m2
A11: electricity | D11: $/kWh
A13: A=I/j=0.25I (m2)
L14: ICC=1.12(electrolyzer)+(0.15+0.08+0.02+0.15)(ICC)
A15: operating days | C15: 300 | D15: days/year
A16: operating hours | C16: =C15*24 -> 7200 | D16: h/year
A19: Pilot scale: 100 L/min feed | G19: Plant scale: 10000 L/min feed
A20: pilot scale area | C20: 4 | D20: m2 | G20: plant scale area | I20: 400 | J20: m2
A21: current | C21: 20 | D21: A | E21: 0.5 mA/cm2 | G21: current | I21: 2000 | J21: A | K21: j | L21: 0.5 mA/cm2
A22: power | C22: =C21*C7/1000 -> 0.01 | D22: kW | G22: power | I22: =I21*C7/1000 -> 1 | J22: kW
A24: Electrolyzer | C24: =SUM(P25:P26) -> 127488 | D24: $ | G24: Electrolyzer | I24: =C10*I20 -> 12748400 | J24: $ | P24: 4m2 | Q24: 400m2
M25: Cell stack cost | O25: 14980 | P25: =4*O25 -> 59920 | Q25: =O25*400 -> 5992000
A26: Installation | C26: 12 | D26: % of equipment | F26: =0.12*C24 -> 15298.56 | G26: Installation | I26: 12 | J26: % of equipment | L26: =0.12*I24 -> 1529808 | M26: Balance of plant cost | O26: 16892 | P26: =4*O26 -> 67568 | Q26: =O26*400 -> 6756800
A27: up-front permitting | C27: 15 | D27: % of installed capital cost | F27: =0.15*$P$29 -> 35696.64 | G27: up-front permitting | I27: 15 | J27: % of installed capital cost | L27: =0.15*$Q$29 -> 3569552
A28: Engineering & design | C28: 8 | D28: % of ICC | F28: =0.08*$P$29 -> 19038.208 | G28: Engineering & design | I28: 8 | J28: % of ICC | L28: =0.08*$Q$29 -> 1903761.1
A29: site prep | C29: 2 | D29: % of ICC | F29: =0.02*$P$29 -> 4759.552 | G29: site prep | I29: 2 | J29: % of ICC | L29: =0.02*$Q$29 -> 475940.27 | M29: ICC | P29: =(1.12/0.6)*C24 -> 237977.6 | Q29: =(1.12/0.6)*I24 -> 23797013
A30: contingency | C30: 15 | D30: % of ICC | F30: =0.15*$P$29 -> 35696.64 | G30: contingency | I30: 15 | J30: % of ICC | L30: =0.15*$Q$29 -> 3569552
A32: CAPEX | C32: =SUM(F26:F30)+SUM(P25:P26) -> 237977.6 | D32: $ | G32: CAPEX | I32: =1.87*I24 -> 23839508 | J32: $
A35: OPEX
A36: Electricity | B36: 0.07 | C36: $/kWh | E36: Sustainable waste-nitrogen upcycling enabled by low-concentration nitrate electrodialysis and high-performance ammonia electrosynthesis - EES Catalysis (RSC Publishing)
A38: Electricity price | C38: =C22*C16*$B$36 -> 5.04 | D38: $/year | G38: Electricity price | I38: =I22*C16*$B$36 -> 504 | J38: $/year
A39: Replacement cost | C39: 15 | D39: % of ICC | G39: Replacement cost | I39: 15 | J39: % of ICC
A40: (every 7year) | C40: =C32*0.15/7 -> 5099.52 | D40: $/year | G40: (every 7year) | I40: =I32*0.15/7 -> 510846.6 | J40: $/year
A41: fixed operation and maintenance | D41: 3% of CAPEXassumed | G41: fixed operation and maintenance | J41: 3% of CAPEXassumed
C42: =C32*0.03 -> 7139.328 | D42: $/year | I42: =I32*0.03 -> 715185.24 | J42: $/year
A44: OPEX | C44: =SUM(C38,C40,C42) -> 12243.888 | D44: $/year | G44: OPEX | I44: =SUM(I38,I40,I42) -> 1226535.8 | J44: $/year
A47: Solvent extraction+electrowinning unit | F47: report.pdf
L48: SX plants are usually expressed in gallons per min ute (gal/min)
A49: 6000-70000 st/d ore tonnage capacity | M49: 1 liter | N49: 0.264172 | O49: gallon
A50: 0.4% Cu and recovery of 50% | E50: assumption
L51: 100 | M51: L/min | N51: = | O51: =L51*N49*15 -> 396.258 | P51: st/d
L54: 6000 | M54: 70000 | N54: st/d
...

Sheet Sheet2
B1: Pilot scale | C1: Plant scale | D1: Unit
A2: Feed input | B2: 100 | C2: 10000 | D2: L/min | G2: Operating days: 300 days/year
A3: Solvent extraction CAPEX | G3: Solvent loss: DCM 1% make up daily
A4: Labor | B4: 99909.8 | C4: 2751744.4 | D4: $ | G4: Ligand loss: ddFc 2% make up daily
A5: Equipment | B5: 256946.58 | C5: 7076896.5 | D5: $
A6: Steel | B6: 49564.68 | C6: 1365124.7 | D6: $
A7: Construction | B7: 306813.43 | C7: 8450343.5 | D7: $
A8: Sales tax | B8: 36224.09 | C8: 997694.34 | D8: $
A9: Initial reagent input | B9: 2847.82 | C9: 284781.93 | D9: $
A10: Total | B10: 752306.4 | C10: 20926585 | D10: $
A11: Solvent extraction OPEX
A12: Labor | B12: 14860.94 | C12: 758658.45 | D12: $/year
A13: Equipment | B13: 7474.69 | C13: 385117.62 | D13: $/year
A14: Steel | B14: 3164.89 | C14: 163053.83 | D14: $/year
A15: Lube | B15: 1676.42 | C15: 83634.19 | D15: $/year
A16: Electricity | B16: 14480.73 | C16: 742660.76 | D16: $/year
A17: Sales tax | B17: 1687.83 | C17: 86962.04 | D17: $/year
A18: Reagent make up | B18: 11833.76 | C18: 1183375.6 | D18: $/year
A19: Total | B19: 55179.26 | C19: 3403462.5 | D19: $/year
A20: Electrolyzer CAPEX
A21: Cell stack cost | B21: 59920 | C21: 5992000 | D21: $
A22: Balance of plant cost | B22: 67568 | C22: 6756800 | D22: $
A23: Installation | B23: 15298.08 | C23: 1529808 | D23: $
A24: Up-front permitting | B24: 35695.52 | C24: 3569552 | D24: $
A25: Engineering & design | B25: 19037.61 | C25: 1903761.1 | D25: $
A26: Site preparation expenses | B26: 4759.4 | C26: 475940.27 | D26: $
A27: Contingency expenses | B27: 35695.52 | C27: 3569552 | D27: $
A28: Total | B28: =SUM(B21:B27) -> 237974.13 | C28: =SUM(C21:C27) -> 23797413 | D28: $
A29: Electrolyzer OPEX
A30: Electricity | B30: 5.04 | C30: 504 | D30: $/year
A31: Replacement cost (every 7 year) | B31: 5108.47 | C31: 510846.6 | D31: $/year
A32: Fixed operation and maintenance | B32: 7151.85 | C32: 715182.24 | D32: $/year
A33: Total | B33: 12265.36 | C33: 1226535.8 | D33: $/year

Sheet Costing 100 Lmin Feed Orig
A1: S1 Stages | B1: S1 C_Pt_in [M] | C1: S1 C_Pd_in [M] | D1: S1 C_Rh_in [M] | E1: S1 q_Pt_in [mol PGM/mol ligand] | F1: S1 q_Pd_in [mol PGM/mol ligand] | G1: S1 q_Rh_in [mol PGM/mol ligand] | H1: S1 C_Pt_out [M] | I1: S1 C_Pd_out [M] | J1: S1 C_Rh_out [M] | K1: S1 q_Pt_out [mol PGM/mol ligand] | L1: S1 q_Pd_out [mol PGM/mol ligand] | M1: S1 q_Rh_out [mol PGM/mol ligand] | N1: S1 Material Residual Pt [mol PGM/time] | O1: S1 Material Residual Pd [mol PGM/time] | P1: S1 Material Residual Rh [mol PGM/time] | Q1: S1 Q_org [L/time] | R1: S1 PGM Recovery [%] | S1: S1 PPM Mass Total Feed [mg/L] | T1: S1 PGM Relative Purity [%] | U1: S1 Q_aq [L/time] | V1: S1 C_lig [L/time] | W1: S1 Q_aq/(Q_org*C_lig) [1/M] | X1: S1 Ligand | Y1: S1 ier | Z1: S1 q_max_Pt | AA1: S1 q_max_Pd | AB1: S1 q_max_Rh | AC1: S1 K_eq_Pt | AD1: S1 K_eq_Pd | AE1: S1 K_eq_Rh | AF1: S2 Stages | AG1: S2 C_Pt_in [M] | AH1: S2 C_Pd_in [M] | AI1: S2 C_Rh_in [M] | AJ1: S2 q_Pt_in [mol PGM/mol ligand] | AK1: S2 q_Pd_in [mol PGM/mol ligand] | AL1: S2 q_Rh_in [mol PGM/mol ligand] | AM1: S2 C_Pt_out [M] | AN1: S2 C_Pd_out [M] | AO1: S2 C_Rh_out [M] | AP1: S2 q_Pt_out [mol PGM/mol ligand] | AQ1: S2 q_Pd_out [mol PGM/mol ligand] | AR1: S2 q_Rh_out [mol PGM/mol ligand] | AS1: S2 Material Residual Pt [mol PGM/time] | AT1: S2 Material Residual Pd [mol PGM/time] | AU1: S2 Material Residual Rh [mol PGM/time] | AV1: S2 Q_org [L/time] | AW1: S2 PGM Recovery [%] | AX1: S2 PPM Mass Total Feed [mg/L] | AY1: S2 PGM Relative Purity [%] | AZ1: S2 Q_aq [L/time] | BA1: S2 C_lig [L/time] | BB1: S2 Q_aq/(Q_org*C_lig) [1/M] | BC1: S2 Ligand | BD1: S2 ier | BE1: S2 q_max_Pt | BF1: S2 q_max_Pd | BG1: S2 q_max_Rh | BH1: S2 K_eq_Pt | BI1: S2 K_eq_Pd | BJ1: S2 K_eq_Rh | BK1: S1 Q_aq Costing [L/min] | BL1: S1 Q_org Costing [L/min] | BM1: S2 Q_aq Costing [L/min] | BN1: S2 Q_org Costing [L/min] | BO1: I- in S1 [mol/min] | BP1: IO3- in S1 [mol/min] | BQ1: H+ in S1 [mol/min] | BR1: I3- [mol/min] | BS1: mols ddFc [mol/min] | BT1: Volume of Ox Prep Reactor [L] | BU1: Vol of Ox RCTR [L] | BV1: Sol Vol Reduction [L/min] | BW1: DI Water Needed in Red [L/min] | BX1: Vol of Red RCTR [L] | BY1: Vol of Precip RCTR [L] | BZ1: mol flow FeCl2 [mol/min] | CA1: ox prep | CB1: ox | CC1: red | CD1: precip | CE1: charge org [L] | CF1: charge lig [mol] | CG1: I- in S2 [mol/min] | CH1: IO3- in S2 [mol/min] | CI1: H+ in S2 [mol/min] | CJ1: I3- [mol/min] | CK1: mols coeFc [mol/min] | CL1: Volume of Ox Prep Reactor [L] | CM1: Vol of Ox RCTR [L] | CN1: Sol Vol Reduction [L/min] | CO1: DI Water Needed in Red [L/min] | CP1: Vol of Red RCTR [L] | CQ1: Vol of Precip RCTR [L] | CR1: mol flow FeCl2 [mol/min] | CS1: ox prep | CT1: ox | CU1: red | CV1: precip | CW1: charge org [L] | CX1: charge lig [mol] | CY1: salt flow S1 [mol/min] | CZ1: salt flow S2 [mol/min] | DA1: cost org chrg S1 | DB1: cost org chrg S2 | DC1: cost lig chrg S1 | DD1: cost lig chrg S2 | DE1: 10000 L/min to ST [for costing] | DK1: S1 labor | DL1: S1 Equip | DM1: S1 Steel | DN1: S1 Const | DO1: S1 Tax | DP1: CAPEX S1 | DQ1: S2 labor | DR1: S2 Equip | DS1: S2 Steel | DT1: S2 Const | DU1: S2 Tax | DV1: CAPEX S2 | DW1: Total CAPEX (2025$) | DX1: Annualized CAPEX assuming 15 year lifetime | DY1: I- in S1 [$/yr] | DZ1: IO3- in S1 [$/yr] | EA1: H+ in S1 [$/yr] | EB1: DCM Makeup S1 [$/yr] | EC1: ddFc Makeup [$/yr] | ED1: Salt S1 [$/yr] | EE1: Reductant S1 [$/yr] | EF1: FeCl2 Precip 1 [$/yr] | EG1: Waste S1 [$/yr] | EH1: I- in S2 [$/yr] | EI1: IO3- in S2 [$/yr] | EJ1: H+ in S2 [$/yr] | EK1: DCM Makeup S2 [$/yr] | EL1: coeFc Makeup [$/yr] | EM1: Salt S2 [$/yr] | EN1: Reductant S2 [$/yr] | EO1: FeCl2 Precip 2 [$/yr] | EP1: Waste S2 [$/yr] | EQ1: chemical opex with tariffs [$/yr] | ER1: total waste [$/yr] | ES1: opex labor S1 | ET1: opex equip S1 | EU1: opex steel S1 | EV1: opex lube S1 | EW1: opex sales tax S1 | EX1: opex S1 | EY1: opex labor S2 | EZ1: opex equip S2 | FA1: opex steel S2 | FB1: opex lube S2 | FC1: opex sales tax S2 | FD1: opex S2 | FE1: opex | FF1: TAC | FG1: Pt | FH1: Pd | FI1: Rh | FJ1: MAX Sales | FK1: PUB | FL1: Cost [$/L feed Process] | FM1: Cost [$/kg Pt Recov] | FN1: Cost [$/kg Pd Recov] | FO1: Cost [$/kg Rh Recov]
A2: 3 | B2: 0.0015414359 | C2: 0.0015414359 | D2: 0.0003425413 | E2: 0 | F2: 0 | G2: 0 | H2: 1.6300359e-05 | I2: 7.447486e-07 | J2: 0.00032385704 | K2: 0.080727109 | L2: 0.081550485 | M2: 0.00098897849 | N2: -9.8011876e-17 | O2: 1.9428903e-16 | P2: -4.3537493e-18 | Q2: 0.18892482 | R2: 94.5454 | S2: 500 | T2: 95 | U2: 1 | V2: 0.1 | W2: 52.931107 | X2: ddFc | Y2: 1 | Z2: 0.28318429 | AA2: 0.56945643 | AB2: 0.0037698629 | AC2: 1822.2108 | AD2: 2662.6059 | AE2: 2401.5031 | AF2: 4 | AG2: 0.0016455479 | AH2: 0.0016623316 | AI2: 2.0159417e-05 | AJ2: 0 | AK2: 0 | AL2: 0 | AM2: 0.0015983351 | AN2: 6.4131851e-05 | AO2: 1.999105e-05 | AP2: 0.0020409859 | AQ2: 0.069089456 | AR2: 7.2784255e-06 | AS2: -1.4297916e-18 | AT2: 2.4286129e-17 | AU2: -3.7851785e-21 | AV2: 0.21439626 | AW2: 99.164823 | AX2: 500 | AY2: 95 | AZ2: 0.92682535 | BA2: 0.1 | BB2: 43.229549 | BC2: coeFc | BD2: 1 | BE2: 0.018775015 | BF2: 0.10492961 | BG2: 0.001814625 | BH2: 285.19514 | BI2: 2169.8945 | BJ2: 866.49409 | BK2: =U2*100 -> 100 | BL2: =Q2*100 -> 18.892482 | BM2: =AZ2*100 -> 92.682535 | BN2: =AV2*100 -> 21.439626 | BO2: =0.6*1.2*BL2/2 -> 6.8012937 | BP2: =0.04*1.2*BL2/2 -> 0.45341958 | BQ2: =0.2*1.2*BL2/2 -> 2.2670979 | BR2: =0.1*1.2*BL2/2 -> 1.1335489 | BS2: =V2*BL2 -> 1.8892482 | BT2: =0.6*BL2*1 -> 11.335489 | BU2: =1.6*BL2*1 -> 30.227972 | BV2: =1*V2*BL2/0.2 -> 9.4462412 | BW2: =BM2-BV2 -> 83.236294 | BX2: =(SUM(BV2:BW2)+BL2)*1 -> 111.57502 | BY2: =BM2 -> 92.682535 | BZ2: =BL2*0.1*1.4 -> 2.6449475 | CA2: =7963.6*(BT2/1000)^0.6*1.7*('CAPEX+OPEX'!$G$116/'CAPEX+OPEX'!$G$115) -> 1086.1882 | CB2: =7963.6*(BU2/1000)^0.6*1.7*('CAPEX+OPEX'!$G$116/'CAPEX+OPEX'!$G$115) -> 1956.5292 | CC2: =7963.6*(BX2/1000)^0.6*1.7*('CAPEX+OPEX'!$G$116/'CAPEX+OPEX'!$G$115) -> 4283.3258 | CD2: =7963.6*(BY2/1000)^0.6*1.7*('CAPEX+OPEX'!$G$116/'CAPEX+OPEX'!$G$115) -> 3832.125 | CE2: 300 | CF2: 30 | CG2: =0.6*1.2*BN2/2 -> 7.7182652 | CH2: =0.04*1.2*BN2/2 -> 0.51455101 | CI2: =0.2*1.2*BN2/2 -> 2.5727551 | CJ2: =0.1*1.2*BN2/2 -> 1.2863775 | CK2: =0.1*BN2 -> 2.1439626 | CL2: =0.6*BN2*1 -> 12.863775 | CM2: =1.6*BN2*1 -> 34.303401 | CN2: =1*BA2*BN2/0.2 -> 10.719813 | CO2: 0 | CP2: =(SUM(CN2:CO2)+BN2)*1 -> 32.159438 | CQ2: =CN2 -> 10.719813 | CR2: =BN2*0.1*1.4 -> 3.0015476 | CS2: =7963.6*(CL2/1000)^0.6*1.7*('CAPEX+OPEX'!$G$116/'CAPEX+OPEX'!$G$115) -> 1171.8229 | CT2: =7963.6*(CM2/1000)^0.6*1.7*('CAPEX+OPEX'!$G$116/'CAPEX+OPEX'!$G$115) -> 2110.7813 | CU2: =7963.6*(CP2/1000)^0.6*1.7*('CAPEX+OPEX'!$G$116/'CAPEX+OPEX'!$G$115) -> 2030.6076 | CV2: =7963.6*(CQ2/1000)^0.6*1.7*('CAPEX+OPEX'!$G$116/'CAPEX+OPEX'!$G$115) -> 1050.3965 | CW2: 300 | CX2: =0.1*CW2 -> 30 | CY2: =0.1*BK2 -> 10 | CZ2: =0.1*BM2 -> 9.2682535 | DA2: =CE2*1.32*10 -> 3960 | DB2: =CW2*1.32*10 -> 3960 | DC2: =CF2*'Reagent cost'!$C$18/1000*'Reagent cost'!$H$18 -> 4784.4136 | DD2: =CX2*'Ligand cost'!$B$56*'Ligand cost'!$J$56 -> 30543.832 | DE2: =10000*1/3.78541*15 -> 39625.827 | DF2: =2510*(DE2^0.571)+89*DE2 -> 4586243.4 | DG2: =4810*(DE2^0.6)+228*DE2 -> 11794835 | DH2: =1030*(DE2^0.59)+44*DE2 -> 2275209.2 | DI2: =5640*(DE2^0.602)+272*DE2 -> 14083914 | DJ2: =688*(DE2^0.6)+32*DE2 -> 1662824.9 | DK2: =DF2*($BK$2/10000)^0.72*0.6*((A2+1)/3)^0.6*('CAPEX+OPEX'!$G$116/'CAPEX+OPEX'!$G$114) -> 277110.06 | DL2: =DG2*($BK$2/10000)^0.72*0.6*((A2+1)/3)^0.6*('CAPEX+OPEX'!$G$116/'CAPEX+OPEX'!$G$114) -> 712667.65 | DM2: =DH2*($BK$2/10000)^0.72*0.6*((A2+1)/3)^0.6*('CAPEX+OPEX'!$G$116/'CAPEX+OPEX'!$G$114) -> 137472.72 | DN2: =DI2*($BK$2/10000)^0.72*0.6*((A2+1)/3)^0.6*('CAPEX+OPEX'!$G$116/'CAPEX+OPEX'!$G$114) -> 850978.45 | DO2: =DJ2*($BK$2/10000)^0.72*0.6*((A2+1)/3)^0.6*('CAPEX+OPEX'!$G$116/'CAPEX+OPEX'!$G$114) -> 100471.23 | DP2: =SUM(DK2:DO2) -> 2078700.1 | DQ2: =DF2*(BM2/10000)^0.72*0.6*((AF2+1)/3)^0.6*('CAPEX+OPEX'!$G$116/'CAPEX+OPEX'!$G$114) -> 299941.66 | DR2: =DG2*(BM2/10000)^0.72*0.6*((AF2+1)/3)^0.6*('CAPEX+OPEX'!$G$116/'CAPEX+OPEX'!$G$114) -> 771385.63 | DS2: =DH2*(BM2/10000)^0.72*0.6*((AF2+1)/3)^0.6*('CAPEX+OPEX'!$G$116/'CAPEX+OPEX'!$G$114) -> 148799.34 | DT2: =DI2*(BM2/10000)^0.72*0.6*((AF2+1)/3)^0.6*('CAPEX+OPEX'!$G$116/'CAPEX+OPEX'!$G$114) -> 921092.11 | DU2: =DJ2*(BM2/10000)^0.72*0.6*((AF2+1)/3)^0.6*('CAPEX+OPEX'!$G$116/'CAPEX+OPEX'!$G$114) -> 108749.23 | DV2: =SUM(DQ2:DU2) -> 2249968 | DW2: =DV2+DP2+SUM(DA2:DD2)*1.15+SUM(CS2:CV2)*1.15+SUM(CA2:CD2)*1.15 -> 4398553.6 | DX2: =DW2/15 -> 293236.91 | DY2: =BO2*'Reagent cost'!$C$35*60*7200 -> 1761651.9 | DZ2: =BP2*'Reagent cost'!$C$34*60*7200 -> 419179.29 | EA2: =BQ2*'Reagent cost'!$C$14*'Reagent cost'!$C$36/1000*60*7200 -> 6948241.5 | EB2: =DA2*0.01 -> 39.6 | EC2: =DC2*0.02 -> 95.688272 | ED2: =0.1*BK2*60*7200*'Reagent cost'!$H$17*'Reagent cost'!$C$17/1000 -> 504921.6 | EE2: =BV2*0.1*'Reagent cost'!$C$16/1000*'Reagent cost'!$H$16*60*7200 -> 1723679.1 | EF2: =BZ2/1000*'Reagent cost'!$H$19*'Reagent cost'!$C$19*60*7200 -> 144826.75 | EG2: =0.33*('Costing 100 Lmin Feed Orig'!BO2*'Reagent cost'!$C$13+'Costing 100 Lmin Feed Orig'!BP2*'Reagent cost'!$C$12+'Costing 100 Lmin Feed Orig'!BQ2*'Reagent cost'!$C$14+'Costing 100 Lmin Feed Orig'!BV2*0.1*'Reagent cost'!$C$16+'Costing 100 Lmin Feed Orig'!BZ2*'Reagent cost'!$C$19)/1000*60*7200 -> 296311.85 | EH2: =CG2*'Reagent cost'!$C$35*60*7200 -> 1999163.3 | EI2: =CH2*'Reagent cost'!$C$34*60*7200 -> 475694.34 | EJ2: =CI2*'Reagent cost'!$C$14*'Reagent cost'!$C$36/1000*60*7200 -> 7885025 | EK2: =DB2*0.01 -> 39.6 | EL2: =DD2*0.02 -> 610.87664 | EM2: =0.1*BM2*60*7200*'Reagent cost'!$H$17*'Reagent cost'!$C$17/1000 -> 467974.14 | EN2: =CN2*0.1*'Reagent cost'!$C$16/1000*'Reagent cost'!$H$16*60*7200 -> 1956070.8 | EO2: =CR2/1000*'Reagent cost'!$H$19*'Reagent cost'!$C$19*60*7200 -> 164352.74 | EP2: =0.33*(CG2*'Reagent cost'!$C$13+CH2*'Reagent cost'!$C$12+CI2*'Reagent cost'!$C$14+CN2*0.1*'Reagent cost'!$C$16+CR2*'Reagent cost'!$C$19)/1000*60*7200 -> 336261.54 | EQ2: =(SUM(DY2:EF2)+SUM(EH2:EO2))*1.2 -> 29341879 | ER2: =EG2+EP2 -> 632573.39 | ES2: =0.499*((BK2/3.78541*15)^(-0.146))*BK2/3.78541*15*300*(1+(A2-2)/9) -> 27520.276 | ET2: =0.248*((BK2/3.78541*15)^(-0.144))*BK2/3.78541*15*300*(1+(A2-2)/3) -> 16610.44 | EU2: =0.105*((BK2/3.78541*15)^(-0.144))*BK2/3.78541*15*300*(1+(A2-2)/3) -> 7032.6458 | EV2: =0.058*((BK2/3.78541*15)^(-0.151))*BK2/3.78541*15*300*(1+(A2-2)/3) -> 3725.3887 | EW2: =0.056*((BK2/3.78541*15)^(-0.144))*BK2/3.78541*15*300*(1+(A2-2)/3) -> 3750.7444 | EX2: =SUM(ES2:EW2) -> 58639.495 | EY2: =0.499*((BM2/3.78541*15)^(-0.146))*BM2/3.78541*15*300*(1+(AF2-2)/9) -> 28370.153 | EZ2: =0.248*((BM2/3.78541*15)^(-0.144))*BM2/3.78541*15*300*(1+(AF2-2)/3) -> 19455.453 | FA2: =0.105*((BM2/3.78541*15)^(-0.144))*BM2/3.78541*15*300*(1+(AF2-2)/3) -> 8237.1877 | FB2: =0.058*((BM2/3.78541*15)^(-0.151))*BM2/3.78541*15*300*(1+(AF2-2)/3) -> 4365.7898 | FC2: =0.056*((BM2/3.78541*15)^(-0.144))*BM2/3.78541*15*300*(1+(AF2-2)/3) -> 4393.1668 | FD2: =SUM(EY2:FC2) -> 64821.751 | FE2: =EQ2+ER2+EX2+FD2 -> 30097914 | FF2: =FE2+DX2 -> 30391151 | FG2: =BM2*AM2*195.08/1000*'PGM market prices'!$C$2*60*7200 -> 4.2109757e+08 | FH2: =BN2*AQ2*BA2*106.42/1000*'PGM market prices'!$C$3*60*7200 -> 2.2424535e+08 | FI2: =BK2*J2*102.91/1000*'PGM market prices'!$C$4*60*7200 -> 2.3748534e+08 | FJ2: =SUM(FG2:FI2) -> 8.8282826e+08 | FK2: =(1-0.26)*(FJ2-FF2) -> 6.3080346e+08 | FL2: =FF2/(BK2*60*7200) -> 0.70349887 | FM2: =FF2/7200/60/(BM2*AM2*195.08/1000) -> 2434.3606 | FN2: =FF2/7200/60/(BN2*BA2*AQ2*106.42/1000) -> 4462.8385 | FO2: =FF2/(J2*BK2*102.91/1000*60*7200) -> 21108.262
A3: 3 | B3: 0.0015414359 | C3: 0.0015414359 | D3: 0.0003425413 | E3: 0 | F3: 0 | G3: 0 | H3: 1.6300359e-05 | I3: 7.447486e-07 | J3: 0.00032385704 | K3: 0.080727109 | L3: 0.081550485 | M3: 0.00098897849 | N3: -9.8011876e-17 | O3: 1.9428903e-16 | P3: -4.3537493e-18 | Q3: 0.18892482 | R3: 94.5454 | S3: 500 | T3: 95 | U3: 1 | V3: 0.1 | W3: 52.931107 | X3: ddFc | Y3: 1 | Z3: 0.28318429 | AA3: 0.56945643 | AB3: 0.0037698629 | AC3: 1822.2108 | AD3: 2662.6059 | AE3: 2401.5031 | AF3: 5 | AG3: 0.0016455479 | AH3: 0.0016623316 | AI3: 2.0159417e-05 | AJ3: 0 | AK3: 0 | AL3: 0 | AM3: 0.0016052842 | AN3: 6.4473619e-05 | AO3: 2.0015023e-05 | AP3: 0.0018300134 | AQ3: 0.072623818 | AR3: 6.562807e-06 | AS3: -1.0199429e-15 | AT3: -2.9988815e-14 | AU3: -1.2040044e-18 | AV3: 0.20391868 | AW3: 99.28374 | AX3: 500 | AY3: 95 | AZ3: 0.92682535 | BA3: 0.1 | BB3: 45.450733 | BC3: coeFc | BD3: 1 | BE3: 0.018775015 | BF3: 0.10492961 | BG3: 0.001814625 | BH3: 285.19514 | BI3: 2169.8945 | BJ3: 866.49409 | BK3: =U3*100 -> 100 | BL3: =Q3*100 -> 18.892482 | BM3: =AZ3*100 -> 92.682535 | BN3: =AV3*100 -> 20.391868 | BO3: =0.6*1.2*BL3/2 -> 6.8012937 | BP3: =0.04*1.2*BL3/2 -> 0.45341958 | BQ3: =0.2*1.2*BL3/2 -> 2.2670979 | BR3: =0.1*1.2*BL3/2 -> 1.1335489 | BS3: =V3*BL3 -> 1.8892482 | BT3: =0.6*BL3*1 -> 11.335489 | BU3: =1.6*BL3*1 -> 30.227972 | BV3: =1*V3*BL3/0.2 -> 9.4462412 | BW3: =BM3-BV3 -> 83.236294 | BX3: =(SUM(BV3:BW3)+BL3)*1 -> 111.57502 | BY3: =BM3 -> 92.682535 | BZ3: =BL3*0.1*1.4 -> 2.6449475 | CA3: =7963.6*(BT3/1000)^0.6*1.7*('CAPEX+OPEX'!$G$116/'CAPEX+OPEX'!$G$115) -> 1086.1882 | CB3: =7963.6*(BU3/1000)^0.6*1.7*('CAPEX+OPEX'!$G$116/'CAPEX+OPEX'!$G$115) -> 1956.5292 | CC3: =7963.6*(BX3/1000)^0.6*1.7*('CAPEX+OPEX'!$G$116/'CAPEX+OPEX'!$G$115) -> 4283.3258 | CD3: =7963.6*(BY3/1000)^0.6*1.7*('CAPEX+OPEX'!$G$116/'CAPEX+OPEX'!$G$115) -> 3832.125 | CE3: 300 | CF3: 30 | CG3: =0.6*1.2*BN3/2 -> 7.3410725 | CH3: =0.04*1.2*BN3/2 -> 0.48940483 | CI3: =0.2*1.2*BN3/2 -> 2.4470242 | CJ3: =0.1*1.2*BN3/2 -> 1.2235121 | CK3: =0.1*BN3 -> 2.0391868 | CL3: =0.6*BN3*1 -> 12.235121 | CM3: =1.6*BN3*1 -> 32.626989 | CN3: =1*BA3*BN3/0.2 -> 10.195934 | CO3: 0 | CP3: =(SUM(CN3:CO3)+BN3)*1 -> 30.587802 | CQ3: =CN3 -> 10.195934 | CR3: =BN3*0.1*1.4 -> 2.8548615 | CS3: =7963.6*(CL3/1000)^0.6*1.7*('CAPEX+OPEX'!$G$116/'CAPEX+OPEX'!$G$115) -> 1137.1189 | CT3: =7963.6*(CM3/1000)^0.6*1.7*('CAPEX+OPEX'!$G$116/'CAPEX+OPEX'!$G$115) -> 2048.2696 | CU3: =7963.6*(CP3/1000)^0.6*1.7*('CAPEX+OPEX'!$G$116/'CAPEX+OPEX'!$G$115) -> 1970.4703 | CV3: =7963.6*(CQ3/1000)^0.6*1.7*('CAPEX+OPEX'!$G$116/'CAPEX+OPEX'!$G$115) -> 1019.2885 | CW3: 300 | CX3: =0.1*CW3 -> 30 | CY3: =0.1*BK3 -> 10 | CZ3: =0.1*BM3 -> 9.2682535 | DA3: =CE3*1.32*10 -> 3960 | DB3: =CW3*1.32*10 -> 3960 | DC3: =CF3*'Reagent cost'!$C$18/1000*'Reagent cost'!$H$18 -> 4784.4136 | DD3: =CX3*'Ligand cost'!$B$56*'Ligand cost'!$J$56 -> 30543.832 | DE3: =10000*1/3.78541*15 -> 39625.827 | DF3: =2510*(DE3^0.571)+89*DE3 -> 4586243.4 | DG3: =4810*(DE3^0.6)+228*DE3 -> 11794835 | DH3: =1030*(DE3^0.59)+44*DE3 -> 2275209.2 | DI3: =5640*(DE3^0.602)+272*DE3 -> 14083914 | DJ3: =688*(DE3^0.6)+32*DE3 -> 1662824.9 | DK3: =DF3*($BK$2/10000)^0.72*0.6*((A3+1)/3)^0.6*('CAPEX+OPEX'!$G$116/'CAPEX+OPEX'!$G$114) -> 277110.06 | DL3: =DG3*($BK$2/10000)^0.72*0.6*((A3+1)/3)^0.6*('CAPEX+OPEX'!$G$116/'CAPEX+OPEX'!$G$114) -> 712667.65 | DM3: =DH3*($BK$2/10000)^0.72*0.6*((A3+1)/3)^0.6*('CAPEX+OPEX'!$G$116/'CAPEX+OPEX'!$G$114) -> 137472.72 | DN3: =DI3*($BK$2/10000)^0.72*0.6*((A3+1)/3)^0.6*('CAPEX+OPEX'!$G$116/'CAPEX+OPEX'!$G$114) -> 850978.45 | DO3: =DJ3*($BK$2/10000)^0.72*0.6*((A3+1)/3)^0.6*('CAPEX+OPEX'!$G$116/'CAPEX+OPEX'!$G$114) -> 100471.23 | DP3: =SUM(DK3:DO3) -> 2078700.1 | DQ3: =DF3*(BM3/10000)^0.72*0.6*((AF3+1)/3)^0.6*('CAPEX+OPEX'!$G$116/'CAPEX+OPEX'!$G$114) -> 334615.1 | DR3: =DG3*(BM3/10000)^0.72*0.6*((AF3+1)/3)^0.6*('CAPEX+OPEX'!$G$116/'CAPEX+OPEX'!$G$114) -> 860558.29 | DS3: =DH3*(BM3/10000)^0.72*0.6*((AF3+1)/3)^0.6*('CAPEX+OPEX'!$G$116/'CAPEX+OPEX'!$G$114) -> 166000.64 | DT3: =DI3*(BM3/10000)^0.72*0.6*((AF3+1)/3)^0.6*('CAPEX+OPEX'!$G$116/'CAPEX+OPEX'!$G$114) -> 1027570.9 | DU3: =DJ3*(BM3/10000)^0.72*0.6*((AF3+1)/3)^0.6*('CAPEX+OPEX'!$G$116/'CAPEX+OPEX'!$G$114) -> 121320.71 | DV3: =SUM(DQ3:DU3) -> 2510065.7 | DW3: =DV3+DP3+SUM(DA3:DD3)*1.15+SUM(CS3:CV3)*1.15+SUM(CA3:CD3)*1.15 -> 4658434.6 | DX3: =DW3/15 -> 310562.3 | DY3: =BO3*'Reagent cost'!$C$35*60*7200 -> 1761651.9 | DZ3: =BP3*'Reagent cost'!$C$34*60*7200 -> 419179.29 | EA3: =BQ3*'Reagent cost'!$C$14*'Reagent cost'!$C$36/1000*60*7200 -> 6948241.5 | EB3: =DA3*0.01 -> 39.6 | EC3: =DC3*0.02 -> 95.688272 | ED3: =0.1*BK3*60*7200*'Reagent cost'!$H$17*'Reagent cost'!$C$17/1000 -> 504921.6 | EE3: =BV3*0.1*'Reagent cost'!$C$16/1000*'Reagent cost'!$H$16*60*7200 -> 1723679.1 | EF3: =BZ3/1000*'Reagent cost'!$H$19*'Reagent cost'!$C$19*60*7200 -> 144826.75 | EG3: =0.33*('Costing 100 Lmin Feed Orig'!BO3*'Reagent cost'!$C$13+'Costing 100 Lmin Feed Orig'!BP3*'Reagent cost'!$C$12+'Costing 100 Lmin Feed Orig'!BQ3*'Reagent cost'!$C$14+'Costing 100 Lmin Feed Orig'!BV3*0.1*'Reagent cost'!$C$16+'Costing 100 Lmin Feed Orig'!BZ3*'Reagent cost'!$C$19)/1000*60*7200 -> 296311.85 | EH3: =CG3*'Reagent cost'!$C$35*60*7200 -> 1901463.9 | EI3: =CH3*'Reagent cost'!$C$34*60*7200 -> 452447.09 | EJ3: =CI3*'Reagent cost'!$C$14*'Reagent cost'!$C$36/1000*60*7200 -> 7499682.7 | EK3: =DB3*0.01 -> 39.6 | EL3: =DD3*0.02 -> 610.87664 | EM3: =0.1*BM3*60*7200*'Reagent cost'!$H$17*'Reagent cost'!$C$17/1000 -> 467974.14 | EN3: =CN3*0.1*'Reagent cost'!$C$16/1000*'Reagent cost'!$H$16*60*7200 -> 1860477.4 | EO3: =CR3/1000*'Reagent cost'!$H$19*'Reagent cost'!$C$19*60*7200 -> 156320.8 | EP3: =0.33*(CG3*'Reagent cost'!$C$13+CH3*'Reagent cost'!$C$12+CI3*'Reagent cost'!$C$14+CN3*0.1*'Reagent cost'!$C$16+CR3*'Reagent cost'!$C$19)/1000*60*7200 -> 319828.39 | EQ3: =(SUM(DY3:EF3)+SUM(EH3:EO3))*1.2 -> 28609982 | ER3: =EG3+EP3 -> 616140.24 | ES3: =0.499*((BK3/3.78541*15)^(-0.146))*BK3/3.78541*15*300*(1+(A3-2)/9) -> 27520.276 | ET3: =0.248*((BK3/3.78541*15)^(-0.144))*BK3/3.78541*15*300*(1+(A3-2)/3) -> 16610.44 | EU3: =0.105*((BK3/3.78541*15)^(-0.144))*BK3/3.78541*15*300*(1+(A3-2)/3) -> 7032.6458 | EV3: =0.058*((BK3/3.78541*15)^(-0.151))*BK3/3.78541*15*300*(1+(A3-2)/3) -> 3725.3887 | EW3: =0.056*((BK3/3.78541*15)^(-0.144))*BK3/3.78541*15*300*(1+(A3-2)/3) -> 3750.7444 | EX3: =SUM(ES3:EW3) -> 58639.495 | EY3: =0.499*((BM3/3.78541*15)^(-0.146))*BM3/3.78541*15*300*(1+(AF3-2)/9) -> 30949.258 | EZ3: =0.248*((BM3/3.78541*15)^(-0.144))*BM3/3.78541*15*300*(1+(AF3-2)/3) -> 23346.544 | FA3: =0.105*((BM3/3.78541*15)^(-0.144))*BM3/3.78541*15*300*(1+(AF3-2)/3) -> 9884.6253 | FB3: =0.058*((BM3/3.78541*15)^(-0.151))*BM3/3.78541*15*300*(1+(AF3-2)/3) -> 5238.9478 | FC3: =0.056*((BM3/3.78541*15)^(-0.144))*BM3/3.78541*15*300*(1+(AF3-2)/3) -> 5271.8002 | FD3: =SUM(EY3:FC3) -> 74691.175 | FE3: =EQ3+ER3+EX3+FD3 -> 29359453 | FF3: =FE3+DX3 -> 29670015 | FG3: =BM3*AM3*195.08/1000*'PGM market prices'!$C$2*60*7200 -> 4.2292838e+08 | FH3: =BN3*AQ3*BA3*106.42/1000*'PGM market prices'!$C$3*60*7200 -> 2.241974e+08 | FI3: =BK3*J3*102.91/1000*'PGM market prices'!$C$4*60*7200 -> 2.3748534e+08 | FJ3: =SUM(FG3:FI3) -> 8.8461111e+08 | FK3: =(1-0.26)*(FJ3-FF3) -> 6.3265641e+08 | FL3: =FF3/(BK3*60*7200) -> 0.68680591 | FM3: =FF3/7200/60/(BM3*AM3*195.08/1000) -> 2366.3089 | FN3: =FF3/7200/60/(BN3*BA3*AQ3*106.42/1000) -> 4357.8741 | FO3: =FF3/(J3*BK3*102.91/1000*60*7200) -> 20607.395
A4: 3 | B4: 0.0015414359 | C4: 0.0015414359 | D4: 0.0003425413 | E4: 0 | F4: 0 | G4: 0 | H4: 1.6300359e-05 | I4: 7.447486e-07 | J4: 0.00032385704 | K4: 0.080727109 | L4: 0.081550485 | M4: 0.00098897849 | N4: -9.8011876e-17 | O4: 1.9428903e-16 | P4: -4.3537493e-18 | Q4: 0.18892482 | R4: 94.5454 | S4: 500 | T4: 95 | U4: 1 | V4: 0.1 | W4: 52.931107 | X4: ddFc | Y4: 1 | Z4: 0.28318429 | AA4: 0.56945643 | AB4: 0.0037698629 | AC4: 1822.2108 | AD4: 2662.6059 | AE4: 2401.5031 | AF4: 6 | AG4: 0.0016455479 | AH4: 0.0016623316 | AI4: 2.0159417e-05 | AJ4: 0 | AK4: 0 | AL4: 0 | AM4: 0.0016074437 | AN4: 6.4579829e-05 | AO4: 2.0022473e-05 | AP4: 0.0017599626 | AQ4: 0.073797327 | AR4: 6.3252067e-06 | AS4: -1.5043305e-18 | AT4: 1.517883e-17 | AU4: -9.2908926e-21 | AV4: 0.20066267 | AW4: 99.320694 | AX4: 500 | AY4: 95 | AZ4: 0.92682535 | BA4: 0.1 | BB4: 46.18823 | BC4: coeFc | BD4: 1 | BE4: 0.018775015 | BF4: 0.10492961 | BG4: 0.001814625 | BH4: 285.19514 | BI4: 2169.8945 | BJ4: 866.49409 | BK4: =U4*100 -> 100 | BL4: =Q4*100 -> 18.892482 | BM4: =AZ4*100 -> 92.682535 | BN4: =AV4*100 -> 20.066267 | BO4: =0.6*1.2*BL4/2 -> 6.8012937 | BP4: =0.04*1.2*BL4/2 -> 0.45341958 | BQ4: =0.2*1.2*BL4/2 -> 2.2670979 | BR4: =0.1*1.2*BL4/2 -> 1.1335489 | BS4: =V4*BL4 -> 1.8892482 | BT4: =0.6*BL4*1 -> 11.335489 | BU4: =1.6*BL4*1 -> 30.227972 | BV4: =1*V4*BL4/0.2 -> 9.4462412 | BW4: =BM4-BV4 -> 83.236294 | BX4: =(SUM(BV4:BW4)+BL4)*1 -> 111.57502 | BY4: =BM4 -> 92.682535 | BZ4: =BL4*0.1*1.4 -> 2.6449475 | CA4: =7963.6*(BT4/1000)^0.6*1.7*('CAPEX+OPEX'!$G$116/'CAPEX+OPEX'!$G$115) -> 1086.1882 | CB4: =7963.6*(BU4/1000)^0.6*1.7*('CAPEX+OPEX'!$G$116/'CAPEX+OPEX'!$G$115) -> 1956.5292 | CC4: =7963.6*(BX4/1000)^0.6*1.7*('CAPEX+OPEX'!$G$116/'CAPEX+OPEX'!$G$115) -> 4283.3258 | CD4: =7963.6*(BY4/1000)^0.6*1.7*('CAPEX+OPEX'!$G$116/'CAPEX+OPEX'!$G$115) -> 3832.125 | CE4: 300 | CF4: 30 | CG4: =0.6*1.2*BN4/2 -> 7.2238562 | CH4: =0.04*1.2*BN4/2 -> 0.48159041 | CI4: =0.2*1.2*BN4/2 -> 2.4079521 | CJ4: =0.1*1.2*BN4/2 -> 1.203976 | CK4: =0.1*BN4 -> 2.0066267 | CL4: =0.6*BN4*1 -> 12.03976 | CM4: =1.6*BN4*1 -> 32.106027 | CN4: =1*BA4*BN4/0.2 -> 10.033134 | CO4: 0 | CP4: =(SUM(CN4:CO4)+BN4)*1 -> 30.099401 | CQ4: =CN4 -> 10.033134 | CR4: =BN4*0.1*1.4 -> 2.8092774 | CS4: =7963.6*(CL4/1000)^0.6*1.7*('CAPEX+OPEX'!$G$116/'CAPEX+OPEX'!$G$115) -> 1126.1899 | CT4: =7963.6*(CM4/1000)^0.6*1.7*('CAPEX+OPEX'!$G$116/'CAPEX+OPEX'!$G$115) -> 2028.5834 | CU4: =7963.6*(CP4/1000)^0.6*1.7*('CAPEX+OPEX'!$G$116/'CAPEX+OPEX'!$G$115) -> 1951.5318 | CV4: =7963.6*(CQ4/1000)^0.6*1.7*('CAPEX+OPEX'!$G$116/'CAPEX+OPEX'!$G$115) -> 1009.492 | CW4: 300 | CX4: =0.1*CW4 -> 30 | CY4: =0.1*BK4 -> 10 | CZ4: =0.1*BM4 -> 9.2682535 | DA4: =CE4*1.32*10 -> 3960 | DB4: =CW4*1.32*10 -> 3960 | DC4: =CF4*'Reagent cost'!$C$18/1000*'Reagent cost'!$H$18 -> 4784.4136 | DD4: =CX4*'Ligand cost'!$B$56*'Ligand cost'!$J$56 -> 30543.832 | DE4: =10000*1/3.78541*15 -> 39625.827 | DF4: =2510*(DE4^0.571)+89*DE4 -> 4586243.4 | DG4: =4810*(DE4^0.6)+228*DE4 -> 11794835 | DH4: =1030*(DE4^0.59)+44*DE4 -> 2275209.2 | DI4: =5640*(DE4^0.602)+272*DE4 -> 14083914 | DJ4: =688*(DE4^0.6)+32*DE4 -> 1662824.9 | DK4: =DF4*($BK$2/10000)^0.72*0.6*((A4+1)/3)^0.6*('CAPEX+OPEX'!$G$116/'CAPEX+OPEX'!$G$114) -> 277110.06 | DL4: =DG4*($BK$2/10000)^0.72*0.6*((A4+1)/3)^0.6*('CAPEX+OPEX'!$G$116/'CAPEX+OPEX'!$G$114) -> 712667.65 | DM4: =DH4*($BK$2/10000)^0.72*0.6*((A4+1)/3)^0.6*('CAPEX+OPEX'!$G$116/'CAPEX+OPEX'!$G$114) -> 137472.72 | DN4: =DI4*($BK$2/10000)^0.72*0.6*((A4+1)/3)^0.6*('CAPEX+OPEX'!$G$116/'CAPEX+OPEX'!$G$114) -> 850978.45 | DO4: =DJ4*($BK$2/10000)^0.72*0.6*((A4+1)/3)^0.6*('CAPEX+OPEX'!$G$116/'CAPEX+OPEX'!$G$114) -> 100471.23 | DP4: =SUM(DK4:DO4) -> 2078700.1 | DQ4: =DF4*(BM4/10000)^0.72*0.6*((AF4+1)/3)^0.6*('CAPEX+OPEX'!$G$116/'CAPEX+OPEX'!$G$114) -> 367040.18 | DR4: =DG4*(BM4/10000)^0.72*0.6*((AF4+1)/3)^0.6*('CAPEX+OPEX'!$G$116/'CAPEX+OPEX'!$G$114) -> 943948.64 | DS4: =DH4*(BM4/10000)^0.72*0.6*((AF4+1)/3)^0.6*('CAPEX+OPEX'!$G$116/'CAPEX+OPEX'!$G$114) -> 182086.54 | DT4: =DI4*(BM4/10000)^0.72*0.6*((AF4+1)/3)^0.6*('CAPEX+OPEX'!$G$116/'CAPEX+OPEX'!$G$114) -> 1127145.2 | DU4: =DJ4*(BM4/10000)^0.72*0.6*((AF4+1)/3)^0.6*('CAPEX+OPEX'!$G$116/'CAPEX+OPEX'!$G$114) -> 133077.01 | DV4: =SUM(DQ4:DU4) -> 2753297.6 | DW4: =DV4+DP4+SUM(DA4:DD4)*1.15+SUM(CS4:CV4)*1.15+SUM(CA4:CD4)*1.15 -> 4901598.3 | DX4: =DW4/15 -> 326773.22 | DY4: =BO4*'Reagent cost'!$C$35*60*7200 -> 1761651.9 | DZ4: =BP4*'Reagent cost'!$C$34*60*7200 -> 419179.29 | EA4: =BQ4*'Reagent cost'!$C$14*'Reagent cost'!$C$36/1000*60*7200 -> 6948241.5 | EB4: =DA4*0.01 -> 39.6 | EC4: =DC4*0.02 -> 95.688272 | ED4: =0.1*BK4*60*7200*'Reagent cost'!$H$17*'Reagent cost'!$C$17/1000 -> 504921.6 | EE4: =BV4*0.1*'Reagent cost'!$C$16/1000*'Reagent cost'!$H$16*60*7200 -> 1723679.1 | EF4: =BZ4/1000*'Reagent cost'!$H$19*'Reagent cost'!$C$19*60*7200 -> 144826.75 | EG4: =0.33*('Costing 100 Lmin Feed Orig'!BO4*'Reagent cost'!$C$13+'Costing 100 Lmin Feed Orig'!BP4*'Reagent cost'!$C$12+'Costing 100 Lmin Feed Orig'!BQ4*'Reagent cost'!$C$14+'Costing 100 Lmin Feed Orig'!BV4*0.1*'Reagent cost'!$C$16+'Costing 100 Lmin Feed Orig'!BZ4*'Reagent cost'!$C$19)/1000*60*7200 -> 296311.85 | EH4: =CG4*'Reagent cost'!$C$35*60*7200 -> 1871102.8 | EI4: =CH4*'Reagent cost'!$C$34*60*7200 -> 445222.78 | EJ4: =CI4*'Reagent cost'!$C$14*'Reagent cost'!$C$36/1000*60*7200 -> 7379933.9 | EK4: =DB4*0.01 -> 39.6 | EL4: =DD4*0.02 -> 610.87664 | EM4: =0.1*BM4*60*7200*'Reagent cost'!$H$17*'Reagent cost'!$C$17/1000 -> 467974.14 | EN4: =CN4*0.1*'Reagent cost'!$C$16/1000*'Reagent cost'!$H$16*60*7200 -> 1830770.8 | EO4: =CR4/1000*'Reagent cost'!$H$19*'Reagent cost'!$C$19*60*7200 -> 153824.79 | EP4: =0.33*(CG4*'Reagent cost'!$C$13+CH4*'Reagent cost'!$C$12+CI4*'Reagent cost'!$C$14+CN4*0.1*'Reagent cost'!$C$16+CR4*'Reagent cost'!$C$19)/1000*60*7200 -> 314721.63 | EQ4: =(SUM(DY4:EF4)+SUM(EH4:EO4))*1.2 -> 28382538 | ER4: =EG4+EP4 -> 611033.48 | ES4: =0.499*((BK4/3.78541*15)^(-0.146))*BK4/3.78541*15*300*(1+(A4-2)/9) -> 27520.276 | ET4: =0.248*((BK4/3.78541*15)^(-0.144))*BK4/3.78541*15*300*(1+(A4-2)/3) -> 16610.44 | EU4: =0.105*((BK4/3.78541*15)^(-0.144))*BK4/3.78541*15*300*(1+(A4-2)/3) -> 7032.6458 | EV4: =0.058*((BK4/3.78541*15)^(-0.151))*BK4/3.78541*15*300*(1+(A4-2)/3) -> 3725.3887 | EW4: =0.056*((BK4/3.78541*15)^(-0.144))*BK4/3.78541*15*300*(1+(A4-2)/3) -> 3750.7444 | EX4: =SUM(ES4:EW4) -> 58639.495 | EY4: =0.499*((BM4/3.78541*15)^(-0.146))*BM4/3.78541*15*300*(1+(AF4-2)/9) -> 33528.363 | EZ4: =0.248*((BM4/3.78541*15)^(-0.144))*BM4/3.78541*15*300*(1+(AF4-2)/3) -> 27237.634 | FA4: =0.105*((BM4/3.78541*15)^(-0.144))*BM4/3.78541*15*300*(1+(AF4-2)/3) -> 11532.063 | FB4: =0.058*((BM4/3.78541*15)^(-0.151))*BM4/3.78541*15*300*(1+(AF4-2)/3) -> 6112.1058 | FC4: =0.056*((BM4/3.78541*15)^(-0.144))*BM4/3.78541*15*300*(1+(AF4-2)/3) -> 6150.4335 | FD4: =SUM(EY4:FC4) -> 84560.599 | FE4: =EQ4+ER4+EX4+FD4 -> 29136772 | FF4: =FE4+DX4 -> 29463545 | FG4: =BM4*AM4*195.08/1000*'PGM market prices'!$C$2*60*7200 -> 4.2349733e+08 | FH4: =BN4*AQ4*BA4*106.42/1000*'PGM market prices'!$C$3*60*7200 -> 2.241825e+08 | FI4: =BK4*J4*102.91/1000*'PGM market prices'!$C$4*60*7200 -> 2.3748534e+08 | FJ4: =SUM(FG4:FI4) -> 8.8516516e+08 | FK4: =(1-0.26)*(FJ4-FF4) -> 6.332192e+08 | FL4: =FF4/(BK4*60*7200) -> 0.6820265 | FM4: =FF4/7200/60/(BM4*AM4*195.08/1000) -> 2346.6851 | FN4: =FF4/7200/60/(BN4*BA4*AQ4*106.42/1000) -> 4327.8358 | FO4: =FF4/(J4*BK4*102.91/1000*60*7200) -> 20463.991
A5: 3 | B5: 0.0015414359 | C5: 0.0015414359 | D5: 0.0003425413 | E5: 0 | F5: 0 | G5: 0 | H5: 1.6300359e-05 | I5: 7.447486e-07 | J5: 0.00032385704 | K5: 0.080727109 | L5: 0.081550485 | M5: 0.00098897849 | N5: -9.8011876e-17 | O5: 1.9428903e-16 | P5: -4.3537493e-18 | Q5: 0.18892482 | R5: 94.5454 | S5: 500 | T5: 95 | U5: 1 | V5: 0.1 | W5: 52.931107 | X5: ddFc | Y5: 1 | Z5: 0.28318429 | AA5: 0.56945643 | AB5: 0.0037698629 | AC5: 1822.2108 | AD5: 2662.6059 | AE5: 2401.5031 | AF5: 7 | AG5: 0.0016455479 | AH5: 0.0016623316 | AI5: 2.0159417e-05 | AJ5: 0 | AK5: 0 | AL5: 0 | AM5: 0.0016080895 | AN5: 6.4611589e-05 | AO5: 2.00247e-05 | AP5: 0.0017385721 | AQ5: 0.074155665 | AR5: 6.2526541e-06 | AS5: -2.2083843e-17 | AT5: -3.749388e-15 | AU5: -5.9159957e-20 | AV5: 0.19968905 | AW5: 99.331744 | AX5: 500 | AY5: 95 | AZ5: 0.92682535 | BA5: 0.1 | BB5: 46.413428 | BC5: coeFc | BD5: 1 | BE5: 0.018775015 | BF5: 0.10492961 | BG5: 0.001814625 | BH5: 285.19514 | BI5: 2169.8945 | BJ5: 866.49409 | BK5: =U5*100 -> 100 | BL5: =Q5*100 -> 18.892482 | BM5: =AZ5*100 -> 92.682535 | BN5: =AV5*100 -> 19.968905 | BO5: =0.6*1.2*BL5/2 -> 6.8012937 | BP5: =0.04*1.2*BL5/2 -> 0.45341958 | BQ5: =0.2*1.2*BL5/2 -> 2.2670979 | BR5: =0.1*1.2*BL5/2 -> 1.1335489 | BS5: =V5*BL5 -> 1.8892482 | BT5: =0.6*BL5*1 -> 11.335489 | BU5: =1.6*BL5*1 -> 30.227972 | BV5: =1*V5*BL5/0.2 -> 9.4462412 | BW5: =BM5-BV5 -> 83.236294 | BX5: =(SUM(BV5:BW5)+BL5)*1 -> 111.57502 | BY5: =BM5 -> 92.682535 | BZ5: =BL5*0.1*1.4 -> 2.6449475 | CA5: =7963.6*(BT5/1000)^0.6*1.7*('CAPEX+OPEX'!$G$116/'CAPEX+OPEX'!$G$115) -> 1086.1882 | CB5: =7963.6*(BU5/1000)^0.6*1.7*('CAPEX+OPEX'!$G$116/'CAPEX+OPEX'!$G$115) -> 1956.5292 | CC5: =7963.6*(BX5/1000)^0.6*1.7*('CAPEX+OPEX'!$G$116/'CAPEX+OPEX'!$G$115) -> 4283.3258 | CD5: =7963.6*(BY5/1000)^0.6*1.7*('CAPEX+OPEX'!$G$116/'CAPEX+OPEX'!$G$115) -> 3832.125 | CE5: 300 | CF5: 30 | CG5: =0.6*1.2*BN5/2 -> 7.1888059 | CH5: =0.04*1.2*BN5/2 -> 0.47925373 | CI5: =0.2*1.2*BN5/2 -> 2.3962686 | CJ5: =0.1*1.2*BN5/2 -> 1.1981343 | CK5: =0.1*BN5 -> 1.9968905 | CL5: =0.6*BN5*1 -> 11.981343 | CM5: =1.6*BN5*1 -> 31.950248 | CN5: =1*BA5*BN5/0.2 -> 9.9844526 | CO5: 0 | CP5: =(SUM(CN5:CO5)+BN5)*1 -> 29.953358 | CQ5: =CN5 -> 9.9844526 | CR5: =BN5*0.1*1.4 -> 2.7956467 | CS5: =7963.6*(CL5/1000)^0.6*1.7*('CAPEX+OPEX'!$G$116/'CAPEX+OPEX'!$G$115) -> 1122.9081 | CT5: =7963.6*(CM5/1000)^0.6*1.7*('CAPEX+OPEX'!$G$116/'CAPEX+OPEX'!$G$115) -> 2022.672 | CU5: =7963.6*(CP5/1000)^0.6*1.7*('CAPEX+OPEX'!$G$116/'CAPEX+OPEX'!$G$115) -> 1945.845 | CV5: =7963.6*(CQ5/1000)^0.6*1.7*('CAPEX+OPEX'!$G$116/'CAPEX+OPEX'!$G$115) -> 1006.5503 | CW5: 300 | CX5: =0.1*CW5 -> 30 | CY5: =0.1*BK5 -> 10 | CZ5: =0.1*BM5 -> 9.2682535 | DA5: =CE5*1.32*10 -> 3960 | DB5: =CW5*1.32*10 -> 3960 | DC5: =CF5*'Reagent cost'!$C$18/1000*'Reagent cost'!$H$18 -> 4784.4136 | DD5: =CX5*'Ligand cost'!$B$56*'Ligand cost'!$J$56 -> 30543.832 | DE5: =10000*1/3.78541*15 -> 39625.827 | DF5: =2510*(DE5^0.571)+89*DE5 -> 4586243.4 | DG5: =4810*(DE5^0.6)+228*DE5 -> 11794835 | DH5: =1030*(DE5^0.59)+44*DE5 -> 2275209.2 | DI5: =5640*(DE5^0.602)+272*DE5 -> 14083914 | DJ5: =688*(DE5^0.6)+32*DE5 -> 1662824.9 | DK5: =DF5*($BK$2/10000)^0.72*0.6*((A5+1)/3)^0.6*('CAPEX+OPEX'!$G$116/'CAPEX+OPEX'!$G$114) -> 277110.06 | DL5: =DG5*($BK$2/10000)^0.72*0.6*((A5+1)/3)^0.6*('CAPEX+OPEX'!$G$116/'CAPEX+OPEX'!$G$114) -> 712667.65 | DM5: =DH5*($BK$2/10000)^0.72*0.6*((A5+1)/3)^0.6*('CAPEX+OPEX'!$G$116/'CAPEX+OPEX'!$G$114) -> 137472.72 | DN5: =DI5*($BK$2/10000)^0.72*0.6*((A5+1)/3)^0.6*('CAPEX+OPEX'!$G$116/'CAPEX+OPEX'!$G$114) -> 850978.45 | DO5: =DJ5*($BK$2/10000)^0.72*0.6*((A5+1)/3)^0.6*('CAPEX+OPEX'!$G$116/'CAPEX+OPEX'!$G$114) -> 100471.23 | DP5: =SUM(DK5:DO5) -> 2078700.1 | DQ5: =DF5*(BM5/10000)^0.72*0.6*((AF5+1)/3)^0.6*('CAPEX+OPEX'!$G$116/'CAPEX+OPEX'!$G$114) -> 397657.14 | DR5: =DG5*(BM5/10000)^0.72*0.6*((AF5+1)/3)^0.6*('CAPEX+OPEX'!$G$116/'CAPEX+OPEX'!$G$114) -> 1022688.9 | DS5: =DH5*(BM5/10000)^0.72*0.6*((AF5+1)/3)^0.6*('CAPEX+OPEX'!$G$116/'CAPEX+OPEX'!$G$114) -> 197275.43 | DT5: =DI5*(BM5/10000)^0.72*0.6*((AF5+1)/3)^0.6*('CAPEX+OPEX'!$G$116/'CAPEX+OPEX'!$G$114) -> 1221167 | DU5: =DJ5*(BM5/10000)^0.72*0.6*((AF5+1)/3)^0.6*('CAPEX+OPEX'!$G$116/'CAPEX+OPEX'!$G$114) -> 144177.73 | DV5: =SUM(DQ5:DU5) -> 2982966.2 | DW5: =DV5+DP5+SUM(DA5:DD5)*1.15+SUM(CS5:CV5)*1.15+SUM(CA5:CD5)*1.15 -> 5131246.3 | DX5: =DW5/15 -> 342083.09 | DY5: =BO5*'Reagent cost'!$C$35*60*7200 -> 1761651.9 | DZ5: =BP5*'Reagent cost'!$C$34*60*7200 -> 419179.29 | EA5: =BQ5*'Reagent cost'!$C$14*'Reagent cost'!$C$36/1000*60*7200 -> 6948241.5 | EB5: =DA5*0.01 -> 39.6 | EC5: =DC5*0.02 -> 95.688272 | ED5: =0.1*BK5*60*7200*'Reagent cost'!$H$17*'Reagent cost'!$C$17/1000 -> 504921.6 | EE5: =BV5*0.1*'Reagent cost'!$C$16/1000*'Reagent cost'!$H$16*60*7200 -> 1723679.1 | EF5: =BZ5/1000*'Reagent cost'!$H$19*'Reagent cost'!$C$19*60*7200 -> 144826.75 | EG5: =0.33*('Costing 100 Lmin Feed Orig'!BO5*'Reagent cost'!$C$13+'Costing 100 Lmin Feed Orig'!BP5*'Reagent cost'!$C$12+'Costing 100 Lmin Feed Orig'!BQ5*'Reagent cost'!$C$14+'Costing 100 Lmin Feed Orig'!BV5*0.1*'Reagent cost'!$C$16+'Costing 100 Lmin Feed Orig'!BZ5*'Reagent cost'!$C$19)/1000*60*7200 -> 296311.85 | EH5: =CG5*'Reagent cost'!$C$35*60*7200 -> 1862024.2 | EI5: =CH5*'Reagent cost'!$C$34*60*7200 -> 443062.56 | EJ5: =CI5*'Reagent cost'!$C$14*'Reagent cost'!$C$36/1000*60*7200 -> 7344126.3 | EK5: =DB5*0.01 -> 39.6 | EL5: =DD5*0.02 -> 610.87664 | EM5: =0.1*BM5*60*7200*'Reagent cost'!$H$17*'Reagent cost'!$C$17/1000 -> 467974.14 | EN5: =CN5*0.1*'Reagent cost'!$C$16/1000*'Reagent cost'!$H$16*60*7200 -> 1821887.8 | EO5: =CR5/1000*'Reagent cost'!$H$19*'Reagent cost'!$C$19*60*7200 -> 153078.43 | EP5: =0.33*(CG5*'Reagent cost'!$C$13+CH5*'Reagent cost'!$C$12+CI5*'Reagent cost'!$C$14+CN5*0.1*'Reagent cost'!$C$16+CR5*'Reagent cost'!$C$19)/1000*60*7200 -> 313194.59 | EQ5: =(SUM(DY5:EF5)+SUM(EH5:EO5))*1.2 -> 28314527 | ER5: =EG5+EP5 -> 609506.44 | ES5: =0.499*((BK5/3.78541*15)^(-0.146))*BK5/3.78541*15*300*(1+(A5-2)/9) -> 27520.276 | ET5: =0.248*((BK5/3.78541*15)^(-0.144))*BK5/3.78541*15*300*(1+(A5-2)/3) -> 16610.44 | EU5: =0.105*((BK5/3.78541*15)^(-0.144))*BK5/3.78541*15*300*(1+(A5-2)/3) -> 7032.6458 | EV5: =0.058*((BK5/3.78541*15)^(-0.151))*BK5/3.78541*15*300*(1+(A5-2)/3) -> 3725.3887 | EW5: =0.056*((BK5/3.78541*15)^(-0.144))*BK5/3.78541*15*300*(1+(A5-2)/3) -> 3750.7444 | EX5: =SUM(ES5:EW5) -> 58639.495 | EY5: =0.499*((BM5/3.78541*15)^(-0.146))*BM5/3.78541*15*300*(1+(AF5-2)/9) -> 36107.468 | EZ5: =0.248*((BM5/3.78541*15)^(-0.144))*BM5/3.78541*15*300*(1+(AF5-2)/3) -> 31128.725 | FA5: =0.105*((BM5/3.78541*15)^(-0.144))*BM5/3.78541*15*300*(1+(AF5-2)/3) -> 13179.5 | FB5: =0.058*((BM5/3.78541*15)^(-0.151))*BM5/3.78541*15*300*(1+(AF5-2)/3) -> 6985.2637 | FC5: =0.056*((BM5/3.78541*15)^(-0.144))*BM5/3.78541*15*300*(1+(AF5-2)/3) -> 7029.0669 | FD5: =SUM(EY5:FC5) -> 94430.024 | FE5: =EQ5+ER5+EX5+FD5 -> 29077103 | FF5: =FE5+DX5 -> 29419186 | FG5: =BM5*AM5*195.08/1000*'PGM market prices'!$C$2*60*7200 -> 4.2366746e+08 | FH5: =BN5*AQ5*BA5*106.42/1000*'PGM market prices'!$C$3*60*7200 -> 2.2417804e+08 | FI5: =BK5*J5*102.91/1000*'PGM market prices'!$C$4*60*7200 -> 2.3748534e+08 | FJ5: =SUM(FG5:FI5) -> 8.8533083e+08 | FK5: =(1-0.26)*(FJ5-FF5) -> 6.3337462e+08 | FL5: =FF5/(BK5*60*7200) -> 0.68099968 | FM5: =FF5/7200/60/(BM5*AM5*195.08/1000) -> 2342.2111 | FN5: =FF5/7200/60/(BN5*BA5*AQ5*106.42/1000) -> 4321.4059 | FO5: =FF5/(J5*BK5*102.91/1000*60*7200) -> 20433.181
